{"name": "Log in with invalid credentials", "status": "failed", "statusDetails": {"message": "AssertionError: assert 'error' in {'errorMessage': 'User does not exist.'}", "trace": "fixturefunc = <function check_error at 0x0000029F90223740>, request = <FixtureRequest for <Function test_log_in_with_invalid_credentials>>, kwargs = {}\n\n    def call_fixture_func(\n        fixturefunc: _FixtureFunc[FixtureValue], request: FixtureRequest, kwargs\n    ) -> FixtureValue:\n        if inspect.isgeneratorfunction(fixturefunc):\n            fixturefunc = cast(Callable[..., Generator[FixtureValue]], fixturefunc)\n            generator = fixturefunc(**kwargs)\n            try:\n                fixture_result = next(generator)\n            except StopIteration:\n                raise ValueError(f\"{request.fixturename} did not yield a value\") from None\n            finalizer = functools.partial(_teardown_yield_fixture, fixturefunc, generator)\n            request.addfinalizer(finalizer)\n        else:\n            fixturefunc = cast(Callable[..., FixtureValue], fixturefunc)\n>           fixture_result = fixturefunc(**kwargs)\n                             ^^^^^^^^^^^^^^^^^^^^^\n\n.venv\\Lib\\site-packages\\_pytest\\fixtures.py:929: \n_ _ _ _ _ _ _ _ _ _ _ _ _ _ _ _ _ _ _ _ _ _ _ _ _ _ _ _ _ _ _ _ _ _ _ _ _ _ _ _ _ _ _ _ _ _ _ _ _ _ _ _ _ _ _ _ _ _ _ _ _ _ _ _ _ _ _ _ _ _ _ _ _ _ _ _ _ _ _ _ _ _ _ _ _ _ _ _ _ _ _ _ _ _ _ _ _ _ _ _ _ _ _ _ _ _ _ _ _ _ _ _ _ _\n\n    @allure.step(\"DeberÃ­a recibir un mensaje de error\")\n    @then(\"I should receive an error message\")\n    def check_error():\n        res = response_data[\"response\"]\n        assert res.status_code == 200\n        data = res.json()\n>       assert \"error\" in data\nE       AssertionError: assert 'error' in {'errorMessage': 'User does not exist.'}\n\nfeatures\\steps\\test_api.py:98: AssertionError"}, "description": "As a user\nI want to sign up and log in to the system\nSo that I can access protected features", "steps": [{"name": "Given I am not a registered user", "status": "passed", "start": 1748962366051, "stop": 1748962366051}, {"name": "When I send a login request with incorrect credentials", "status": "passed", "start": 1748962366052, "stop": 1748962366318}, {"name": "Then I should receive an error message", "status": "failed", "statusDetails": {"message": "AssertionError: assert 'error' in {'errorMessage': 'User does not exist.'}\n", "trace": "  File \"C:\\Users\\daviv\\OneDrive\\Documentos\\demoblazeTesting\\.venv\\Lib\\site-packages\\pytest_bdd\\scenario.py\", line 240, in _execute_step_function\n    return_value = call_fixture_func(fixturefunc=context.step_func, request=request, kwargs=kwargs)\n                   ^^^^^^^^^^^^^^^^^^^^^^^^^^^^^^^^^^^^^^^^^^^^^^^^^^^^^^^^^^^^^^^^^^^^^^^^^^^^^^^^\n  File \"C:\\Users\\daviv\\OneDrive\\Documentos\\demoblazeTesting\\.venv\\Lib\\site-packages\\_pytest\\fixtures.py\", line 929, in call_fixture_func\n    fixture_result = fixturefunc(**kwargs)\n                     ^^^^^^^^^^^^^^^^^^^^^\n  File \"C:\\Users\\daviv\\OneDrive\\Documentos\\demoblazeTesting\\features\\steps\\test_api.py\", line 98, in check_error\n    assert \"error\" in data\n"}, "start": 1748962366318, "stop": 1748962366319}], "start": 1748962366051, "stop": 1748962366319, "uuid": "30ff52ee-eced-05d8-ef31-b6c69014a236", "historyId": "6b98a6f6d51ae7e633a0040ae12a67f8.d41d8cd98f00b204e9800998ecf8427e", "testCaseId": "6b98a6f6d51ae7e633a0040ae12a67f8", "fullName": "features\\login_api.feature:Log in with invalid credentials", "labels": [{"name": "host", "value": "vidd4"}, {"name": "thread", "value": "19752-MainThread"}, {"name": "framework", "value": "pytest-bdd"}, {"name": "language", "value": "cpython3"}, {"name": "feature", "value": "User Authentication"}]}